Workbook

Sheet Sprint Planning
A1: Sprint Planning
A2: Plan original de cada sprint (Guía 1.5) y lo que se incorporó durante su ejecución.
A4: Sprint 1
A5: Fechas | B5: =Parámetros!$D$9 -> 46272 | C5: =Parámetros!$E$9 -> 46292 | D5: Semanas 5 a 7
A6: Objetivo del sprint | B6: Contar con el catálogo oficial del ISP normalizado y la base de datos lista para recibir datos.
A7: Capacidad (horas) | B7: =2*Parámetros!$B$6*3 -> 72 | C7: 2 integrantes × horas semanales × 3 semanas
A8: Compromiso | B8: ID | C8: Historia | D8: Story points | E8: Estado actual | F8: Sprint en que se terminó
A9: Planificada | B9: HU01 | C9: =INDEX('Historias de Usuario'!$C$5:$C$33,MATCH(B9,'Historias de Usuario'!$A$5:$A$33,0)) -> Como equipo de datos, quiero consolidar los tres listados del ISP (referentes, alternativas e híbridos) en un solo archivo, para trabajar con una única fuente oficial. | D9: =INDEX('Historias de Usuario'!$E$5:$E$33,MATCH(B9,'Historias de Usuario'!$A$5:$A$33,0)) -> 3 | E9: =INDEX('Historias de Usuario'!$J$5:$J$33,MATCH(B9,'Historias de Usuario'!$A$5:$A$33,0)) -> Terminada | F9: =INDEX('Historias de Usuario'!$I$5:$I$33,MATCH(B9,'Historias de Usuario'!$A$5:$A$33,0)) -> 1
A10: Planificada | B10: HU02 | C10: =INDEX('Historias de Usuario'!$C$5:$C$33,MATCH(B10,'Historias de Usuario'!$A$5:$A$33,0)) -> Como equipo de datos, quiero separar registro y año, forma farmacéutica, dosis y principios activos del catálogo del ISP, para cargar medicamentos y composición en tablas separadas. | D10: =INDEX('Historias de Usuario'!$E$5:$E$33,MATCH(B10,'Historias de Usuario'!$A$5:$A$33,0)) -> 8 | E10: =INDEX('Historias de Usuario'!$J$5:$J$33,MATCH(B10,'Historias de Usuario'!$A$5:$A$33,0)) -> Terminada | F10: =INDEX('Historias de Usuario'!$I$5:$I$33,MATCH(B10,'Historias de Usuario'!$A$5:$A$33,0)) -> 1
A11: Planificada | B11: HU07 | C11: =INDEX('Historias de Usuario'!$C$5:$C$33,MATCH(B11,'Historias de Usuario'!$A$5:$A$33,0)) -> Como equipo, quiero revisar el robots.txt de cada fuente, aplicar pausas e identificarnos como proyecto académico, para extraer datos de forma ética y legal. | D11: =INDEX('Historias de Usuario'!$E$5:$E$33,MATCH(B11,'Historias de Usuario'!$A$5:$A$33,0)) -> 3 | E11: =INDEX('Historias de Usuario'!$J$5:$J$33,MATCH(B11,'Historias de Usuario'!$A$5:$A$33,0)) -> En curso | F11: =INDEX('Historias de Usuario'!$I$5:$I$33,MATCH(B11,'Historias de Usuario'!$A$5:$A$33,0)) -> 1
A12: Planificada | B12: HU12 | C12: =INDEX('Historias de Usuario'!$C$5:$C$33,MATCH(B12,'Historias de Usuario'!$A$5:$A$33,0)) -> Como equipo, quiero un esquema relacional en PostgreSQL ejecutándose en Docker, para persistir catálogo, oferta y precios. | D12: =INDEX('Historias de Usuario'!$E$5:$E$33,MATCH(B12,'Historias de Usuario'!$A$5:$A$33,0)) -> 5 | E12: =INDEX('Historias de Usuario'!$J$5:$J$33,MATCH(B12,'Historias de Usuario'!$A$5:$A$33,0)) -> Terminada | F12: =INDEX('Historias de Usuario'!$I$5:$I$33,MATCH(B12,'Historias de Usuario'!$A$5:$A$33,0)) -> 1
A13: Planificada | B13: HU13 | C13: =INDEX('Historias de Usuario'!$C$5:$C$33,MATCH(B13,'Historias de Usuario'!$A$5:$A$33,0)) -> Como analista, quiero que cada ejecución agregue el precio del día sin duplicarlo, para construir un historial confiable. | D13: =INDEX('Historias de Usuario'!$E$5:$E$33,MATCH(B13,'Historias de Usuario'!$A$5:$A$33,0)) -> 5 | E13: =INDEX('Historias de Usuario'!$J$5:$J$33,MATCH(B13,'Historias de Usuario'!$A$5:$A$33,0)) -> Terminada | F13: =INDEX('Historias de Usuario'!$I$5:$I$33,MATCH(B13,'Historias de Usuario'!$A$5:$A$33,0)) -> 1
A14: Incorporada durante el sprint | B14: HU03 | C14: =INDEX('Historias de Usuario'!$C$5:$C$33,MATCH(B14,'Historias de Usuario'!$A$5:$A$33,0)) -> Como paciente, quiero que BioEqui incluya los precios de Dr. Simi, para compararlos con los de otras farmacias. | D14: =INDEX('Historias de Usuario'!$E$5:$E$33,MATCH(B14,'Historias de Usuario'!$A$5:$A$33,0)) -> 5 | E14: =INDEX('Historias de Usuario'!$J$5:$J$33,MATCH(B14,'Historias de Usuario'!$A$5:$A$33,0)) -> Terminada | F14: =INDEX('Historias de Usuario'!$I$5:$I$33,MATCH(B14,'Historias de Usuario'!$A$5:$A$33,0)) -> 1
A15: Incorporada durante el sprint | B15: HU04 | C15: =INDEX('Historias de Usuario'!$C$5:$C$33,MATCH(B15,'Historias de Usuario'!$A$5:$A$33,0)) -> Como paciente, quiero que BioEqui incluya los precios de Cruz Verde, para comparar con la cadena de mayor catálogo. | D15: =INDEX('Historias de Usuario'!$E$5:$E$33,MATCH(B15,'Historias de Usuario'!$A$5:$A$33,0)) -> 8 | E15: =INDEX('Historias de Usuario'!$J$5:$J$33,MATCH(B15,'Historias de Usuario'!$A$5:$A$33,0)) -> Terminada con observación | F15: =INDEX('Historias de Usuario'!$I$5:$I$33,MATCH(B15,'Historias de Usuario'!$A$5:$A$33,0)) -> 1
A16: Incorporada durante el sprint | B16: HU05 | C16: =INDEX('Historias de Usuario'!$C$5:$C$33,MATCH(B16,'Historias de Usuario'!$A$5:$A$33,0)) -> Como paciente, quiero que BioEqui incluya los precios de Ahumada, para ampliar la comparación. | D16: =INDEX('Historias de Usuario'!$E$5:$E$33,MATCH(B16,'Historias de Usuario'!$A$5:$A$33,0)) -> 8 | E16: =INDEX('Historias de Usuario'!$J$5:$J$33,MATCH(B16,'Historias de Usuario'!$A$5:$A$33,0)) -> Terminada | F16: =INDEX('Historias de Usuario'!$I$5:$I$33,MATCH(B16,'Historias de Usuario'!$A$5:$A$33,0)) -> 1
A17: Incorporada durante el sprint | B17: HU06 | C17: =INDEX('Historias de Usuario'!$C$5:$C$33,MATCH(B17,'Historias de Usuario'!$A$5:$A$33,0)) -> Como paciente, quiero que BioEqui incluya los precios de Profar, para sumar una cuarta cadena. | D17: =INDEX('Historias de Usuario'!$E$5:$E$33,MATCH(B17,'Historias de Usuario'!$A$5:$A$33,0)) -> 5 | E17: =INDEX('Historias de Usuario'!$J$5:$J$33,MATCH(B17,'Historias de Usuario'!$A$5:$A$33,0)) -> Terminada con observación | F17: =INDEX('Historias de Usuario'!$I$5:$I$33,MATCH(B17,'Historias de Usuario'!$A$5:$A$33,0)) -> 1
A18: Incorporada durante el sprint | B18: HU08 | C18: =INDEX('Historias de Usuario'!$C$5:$C$33,MATCH(B18,'Historias de Usuario'!$A$5:$A$33,0)) -> Como equipo de datos, quiero vincular cada producto de farmacia con el catálogo del ISP por la raíz del registro sanitario, para saber qué productos están respaldados por el registro oficial. | D18: =INDEX('Historias de Usuario'!$E$5:$E$33,MATCH(B18,'Historias de Usuario'!$A$5:$A$33,0)) -> 5 | E18: =INDEX('Historias de Usuario'!$J$5:$J$33,MATCH(B18,'Historias de Usuario'!$A$5:$A$33,0)) -> Terminada | F18: =INDEX('Historias de Usuario'!$I$5:$I$33,MATCH(B18,'Historias de Usuario'!$A$5:$A$33,0)) -> 1
A19: Incorporada durante el sprint | B19: HU09 | C19: =INDEX('Historias de Usuario'!$C$5:$C$33,MATCH(B19,'Historias de Usuario'!$A$5:$A$33,0)) -> Como equipo de datos, quiero validar las vinculaciones y apartar las dudosas, para no agrupar medicamentos distintos. | D19: =INDEX('Historias de Usuario'!$E$5:$E$33,MATCH(B19,'Historias de Usuario'!$A$5:$A$33,0)) -> 5 | E19: =INDEX('Historias de Usuario'!$J$5:$J$33,MATCH(B19,'Historias de Usuario'!$A$5:$A$33,0)) -> Terminada | F19: =INDEX('Historias de Usuario'!$I$5:$I$33,MATCH(B19,'Historias de Usuario'!$A$5:$A$33,0)) -> 1
A20: Incorporada durante el sprint | B20: HU10 | C20: =INDEX('Historias de Usuario'!$C$5:$C$33,MATCH(B20,'Historias de Usuario'!$A$5:$A$33,0)) -> Como paciente, quiero que solo se comparen productos realmente intercambiables, para no comparar presentaciones distintas. | D20: =INDEX('Historias de Usuario'!$E$5:$E$33,MATCH(B20,'Historias de Usuario'!$A$5:$A$33,0)) -> 8 | E20: =INDEX('Historias de Usuario'!$J$5:$J$33,MATCH(B20,'Historias de Usuario'!$A$5:$A$33,0)) -> Terminada | F20: =INDEX('Historias de Usuario'!$I$5:$I$33,MATCH(B20,'Historias de Usuario'!$A$5:$A$33,0)) -> 1
... A26: Incorporada durante el sprint | B26: HU20 | C26: =INDEX('Historias de Usuario'!$C$5:$C$33,MATCH(B26,'Historias de Usuario'!$A$5:$A$33,0)) -> Como paciente, quiero ver la fecha del precio y una advertencia de uso informativo, para no confundir un precio antiguo con uno vigente. | D26: =INDEX('Historias de Usuario'!$E$5:$E$33,MATCH(B26,'Historias de Usuario'!$A$5:$A$33,0)) -> 2 | E26: =INDEX('Historias de Usuario'!$J$5:$J$33,MATCH(B26,'Historias de Usuario'!$A$5:$A$33,0)) -> Terminada | F26: =INDEX('Historias de Usuario'!$I$5:$I$33,MATCH(B26,'Historias de Usuario'!$A$5:$A$33,0)) -> 1
C27: Story points planificados | D27: =SUMIF(A9:A26,"Planificada",D9:D26) -> 24
C28: Story points terminados en el sprint (velocidad) | D28: =SUMIFS('Historias de Usuario'!$E$5:$E$33,'Historias de Usuario'!$I$5:$I$33,1,'Historias de Usuario'!$J$5:$J$33,"Terminada*") -> 91
A29: Resultado | B29: Se cumplió el objetivo y se adelantó trabajo de los sprints 2 y 3: cuatro extractores, capa oro, API y primera versión de la página.
A31: Sprint 2
A32: Fechas | B32: =Parámetros!$D$10 -> 46293 | C32: =Parámetros!$E$10 -> 46313 | D32: Semanas 8 a 10
A33: Objetivo del sprint | B33: Integrar las farmacias y obtener los primeros grupos de productos comparables.
A34: Capacidad (horas) | B34: =2*Parámetros!$B$6*3 -> 72 | C34: 2 integrantes × horas semanales × 3 semanas
A35: Compromiso | B35: ID | C35: Historia | D35: Story points | E35: Estado actual | F35: Sprint en que se terminó
A36: Planificada | B36: HU03 | C36: =INDEX('Historias de Usuario'!$C$5:$C$33,MATCH(B36,'Historias de Usuario'!$A$5:$A$33,0)) -> Como paciente, quiero que BioEqui incluya los precios de Dr. Simi, para compararlos con los de otras farmacias. | D36: =INDEX('Historias de Usuario'!$E$5:$E$33,MATCH(B36,'Historias de Usuario'!$A$5:$A$33,0)) -> 5 | E36: =INDEX('Historias de Usuario'!$J$5:$J$33,MATCH(B36,'Historias de Usuario'!$A$5:$A$33,0)) -> Terminada | F36: =INDEX('Historias de Usuario'!$I$5:$I$33,MATCH(B36,'Historias de Usuario'!$A$5:$A$33,0)) -> 1
A37: Planificada | B37: HU04 | C37: =INDEX('Historias de Usuario'!$C$5:$C$33,MATCH(B37,'Historias de Usuario'!$A$5:$A$33,0)) -> Como paciente, quiero que BioEqui incluya los precios de Cruz Verde, para comparar con la cadena de mayor catálogo. | D37: =INDEX('Historias de Usuario'!$E$5:$E$33,MATCH(B37,'Historias de Usuario'!$A$5:$A$33,0)) -> 8 | E37: =INDEX('Historias de Usuario'!$J$5:$J$33,MATCH(B37,'Historias de Usuario'!$A$5:$A$33,0)) -> Terminada con observación | F37: =INDEX('Historias de Usuario'!$I$5:$I$33,MATCH(B37,'Historias de Usuario'!$A$5:$A$33,0)) -> 1
A38: Planificada | B38: HU05 | C38: =INDEX('Historias de Usuario'!$C$5:$C$33,MATCH(B38,'Historias de Usuario'!$A$5:$A$33,0)) -> Como paciente, quiero que BioEqui incluya los precios de Ahumada, para ampliar la comparación. | D38: =INDEX('Historias de Usuario'!$E$5:$E$33,MATCH(B38,'Historias de Usuario'!$A$5:$A$33,0)) -> 8 | E38: =INDEX('Historias de Usuario'!$J$5:$J$33,MATCH(B38,'Historias de Usuario'!$A$5:$A$33,0)) -> Terminada | F38: =INDEX('Historias de Usuario'!$I$5:$I$33,MATCH(B38,'Historias de Usuario'!$A$5:$A$33,0)) -> 1
A39: Planificada | B39: HU08 | C39: =INDEX('Historias de Usuario'!$C$5:$C$33,MATCH(B39,'Historias de Usuario'!$A$5:$A$33,0)) -> Como equipo de datos, quiero vincular cada producto de farmacia con el catálogo del ISP por la raíz del registro sanitario, para saber qué productos están respaldados por el registro oficial. | D39: =INDEX('Historias de Usuario'!$E$5:$E$33,MATCH(B39,'Historias de Usuario'!$A$5:$A$33,0)) -> 5 | E39: =INDEX('Historias de Usuario'!$J$5:$J$33,MATCH(B39,'Historias de Usuario'!$A$5:$A$33,0)) -> Terminada | F39: =INDEX('Historias de Usuario'!$I$5:$I$33,MATCH(B39,'Historias de Usuario'!$A$5:$A$33,0)) -> 1
A40: Planificada | B40: HU09 | C40: =INDEX('Historias de Usuario'!$C$5:$C$33,MATCH(B40,'Historias de Usuario'!$A$5:$A$33,0)) -> Como equipo de datos, quiero validar las vinculaciones y apartar las dudosas, para no agrupar medicamentos distintos. | D40: =INDEX('Historias de Usuario'!$E$5:$E$33,MATCH(B40,'Historias de Usuario'!$A$5:$A$33,0)) -> 5 | E40: =INDEX('Historias de Usuario'!$J$5:$J$33,MATCH(B40,'Historias de Usuario'!$A$5:$A$33,0)) -> Terminada | F40: =INDEX('Historias de Usuario'!$I$5:$I$33,MATCH(B40,'Historias de Usuario'!$A$5:$A$33,0)) -> 1
A41: Planificada | B41: HU10 | C41: =INDEX('Historias de Usuario'!$C$5:$C$33,MATCH(B41,'Historias de Usuario'!$A$5:$A$33,0)) -> Como paciente, quiero que solo se comparen productos realmente intercambiables, para no comparar presentaciones distintas. | D41: =INDEX('Historias de Usuario'!$E$5:$E$33,MATCH(B41,'Historias de Usuario'!$A$5:$A$33,0)) -> 8 | E41: =INDEX('Historias de Usuario'!$J$5:$J$33,MATCH(B41,'Historias de Usuario'!$A$5:$A$33,0)) -> Terminada | F41: =INDEX('Historias de Usuario'!$I$5:$I$33,MATCH(B41,'Historias de Usuario'!$A$5:$A$33,0)) -> 1
A42: Planificada | B42: HU11 | C42: =INDEX('Historias de Usuario'!$C$5:$C$33,MATCH(B42,'Historias de Usuario'!$A$5:$A$33,0)) -> Como paciente, quiero saber si la bioequivalencia la certifica el ISP o solo la declara la farmacia, para saber cuánto confiar en el dato. | D42: =INDEX('Historias de Usuario'!$E$5:$E$33,MATCH(B42,'Historias de Usuario'!$A$5:$A$33,0)) -> 3 | E42: =INDEX('Historias de Usuario'!$J$5:$J$33,MATCH(B42,'Historias de Usuario'!$A$5:$A$33,0)) -> Terminada | F42: =INDEX('Historias de Usuario'!$I$5:$I$33,MATCH(B42,'Historias de Usuario'!$A$5:$A$33,0)) -> 1
A43: Planificada | B43: HU27 | C43: =INDEX('Historias de Usuario'!$C$5:$C$33,MATCH(B43,'Historias de Usuario'!$A$5:$A$33,0)) -> Como analista, quiero muestrear los precios de las farmacias periódicamente, para acumular historial. | D43: =INDEX('Historias de Usuario'!$E$5:$E$33,MATCH(B43,'Historias de Usuario'!$A$5:$A$33,0)) -> 3 | E43: =INDEX('Historias de Usuario'!$J$5:$J$33,MATCH(B43,'Historias de Usuario'!$A$5:$A$33,0)) -> Terminada | F43: =INDEX('Historias de Usuario'!$I$5:$I$33,MATCH(B43,'Historias de Usuario'!$A$5:$A$33,0)) -> 2
A44: Planificada | B44: HU28 | C44: =INDEX('Historias de Usuario'!$C$5:$C$33,MATCH(B44,'Historias de Usuario'!$A$5:$A$33,0)) -> Como equipo, quiero el código centralizado en Desarrollo_Proyecto y un flujo develop → main, para entregar un repositorio ordenado. | D44: =INDEX('Historias de Usuario'!$E$5:$E$33,MATCH(B44,'Historias de Usuario'!$A$5:$A$33,0)) -> 3 | E44: =INDEX('Historias de Usuario'!$J$5:$J$33,MATCH(B44,'Historias de Usuario'!$A$5:$A$33,0)) -> Terminada | F44: =INDEX('Historias de Usuario'!$I$5:$I$33,MATCH(B44,'Historias de Usuario'!$A$5:$A$33,0)) -> 2
A45: Planificada | B45: HU29 | C45: =INDEX('Historias de Usuario'!$C$5:$C$33,MATCH(B45,'Historias de Usuario'!$A$5:$A$33,0)) -> Como equipo, quiero un entorno reproducible (requirements.txt y docker-compose v2), para que cualquiera levante el sistema. | D45: =INDEX('Historias de Usuario'!$E$5:$E$33,MATCH(B45,'Historias de Usuario'!$A$5:$A$33,0)) -> 3 | E45: =INDEX('Historias de Usuario'!$J$5:$J$33,MATCH(B45,'Historias de Usuario'!$A$5:$A$33,0)) -> Terminada | F45: =INDEX('Historias de Usuario'!$I$5:$I$33,MATCH(B45,'Historias de Usuario'!$A$5:$A$33,0)) -> 2
C46: Story points planificados | D46: =SUMIF(A36:A45,"Planificada",D36:D45) -> 51
C47: Story points terminados en el sprint (velocidad) | D47: =SUMIFS('Historias de Usuario'!$E$5:$E$33,'Historias de Usuario'!$I$5:$I$33,2,'Historias de Usuario'!$J$5:$J$33,"Terminada*") -> 9
...

Sheet Parámetros
A1: Parámetros del calendario
A2: Cambia la fecha de inicio y todas las fechas de sprint se recalculan.
A4: Inicio del semestre (lunes de la semana 1) | B4: 46244 | C4: Supuesto: verificar con el calendario de la asignatura.
A5: Fecha de corte de estos documentos | B5: 46310
A6: Horas semanales por integrante | B6: 12 | C6: Supuesto para calcular la capacidad: ajustar.
A8: Sprint | B8: Semana inicio | C8: Semana fin | D8: Fecha inicio | E8: Fecha fin | F8: Objetivo planificado
A9: 1 | B9: 5 | C9: 7 | D9: =$B$4+(B9-1)*7 -> 46272 | E9: =$B$4+C9*7-1 -> 46292 | F9: Contar con el catálogo oficial del ISP normalizado y la base de datos lista para recibir datos.
A10: 2 | B10: 8 | C10: 10 | D10: =$B$4+(B10-1)*7 -> 46293 | E10: =$B$4+C10*7-1 -> 46313 | F10: Integrar las farmacias y obtener los primeros grupos de productos comparables.
A11: 3 | B11: 11 | C11: 13 | D11: =$B$4+(B11-1)*7 -> 46314 | E11: =$B$4+C11*7-1 -> 46334 | F11: Cerrar brechas de calidad y cumplimiento: métricas con las cuatro farmacias, credenciales fuera del repositorio, ajustes de extracción y mejoras de la página.
A12: 4 | B12: 14 | C12: 16 | D12: =$B$4+(B12-1)*7 -> 46335 | E12: =$B$4+C12*7-1 -> 46355 | F12: Asegurar calidad, automatizar la actualización y documentar para la entrega final.

Sheet Historias de Usuario
A1: Historias de usuario
A2: Estimación en story points (Fibonacci). Prioridad MoSCoW. Valor de negocio de 1 a 5.
A3: Celdas en amarillo: completar o verificar con información del equipo.
A4: ID | B4: Épica | C4: Historia de usuario | D4: Criterios de aceptación | E4: Story points | F4: Prioridad | G4: Valor | H4: Sprint planificado | I4: Sprint real | J4: Estado | K4: Responsable | L4: Fecha de término | M4: Evidencia (commit)
A5: HU01 | B5: E1 | C5: Como equipo de datos, quiero consolidar los tres listados del ISP (referentes, alternativas e híbridos) en un solo archivo, para trabajar con una única fuente oficial. | D5: • Dado los tres archivos del ISP (HTML con extensión .xls, codificación latin-1), cuando ejecuto consolidar_isp.py, entonces obtengo un único archivo con una columna que indica el listado de origen. • El total de filas coincide con la suma de los tres listados. | E5: 3 | F5: Must | G5: 5 | H5: 1 | I5: 1 | J5: Terminada | K5: Diego Fuentes e Iván Fernández | L5: 46273 | M5: 80c9715 · c2da72a
A6: HU02 | B6: E1 | C6: Como equipo de datos, quiero separar registro y año, forma farmacéutica, dosis y principios activos del catálogo del ISP, para cargar medicamentos y composición en tablas separadas. | D6: • Dado un registro "F-8660/11", entonces la raíz guardada es "F-8660". • Dada una dosis "160 mg/5 mL", entonces se guarda en cuatro campos (valor, unidad, referencia, unidad de referencia). • Dado un producto combinado, entonces se genera una fila de composición por principio activo. | E6: 8 | F6: Must | G6: 5 | H6: 1 | I6: 1 | J6: Terminada | K6: Diego Fuentes | L6: 46273 | M6: c2da72a
A7: HU03 | B7: E2 | C7: Como paciente, quiero que BioEqui incluya los precios de Dr. Simi, para compararlos con los de otras farmacias. | D7: • Dado el catálogo público de Dr. Simi (API de la plataforma VTEX), cuando se ejecuta la descarga, entonces se recorren sus categorías con 2 s de pausa y un User-Agent que identifica al proyecto académico. • Cada dato se extrae por nombre de campo, no por posición. | E7: 5 | F7: Must | G7: 5 | H7: 2 | I7: 1 | J7: Terminada | K7: Diego Fuentes e Iván Fernández | L7: 46273 | M7: 21b5918 · 0219a74 · c2da72a
A8: HU04 | B8: E2 | C8: Como paciente, quiero que BioEqui incluya los precios de Cruz Verde, para comparar con la cadena de mayor catálogo. | D8: • Dado el catálogo de Cruz Verde, cuando se normaliza, entonces el principio activo se identifica en el nombre usando la lista oficial del ISP. • Ante errores 429/5xx el extractor reintenta hasta 3 veces antes de detenerse. • La extracción cumple las reglas de la épica E8 (ver HU07 e IMP-12). | E8: 8 | F8: Must | G8: 4 | H8: 2 | I8: 1 | J8: Terminada con observación | K8: Diego Fuentes e Iván Fernández | L8: 46275 | M8: dd5ceea · 376552f
A9: HU05 | B9: E2 | C9: Como paciente, quiero que BioEqui incluya los precios de Ahumada, para ampliar la comparación. | D9: • La paginación usa un parámetro permitido por el robots.txt del sitio. • Las fichas de producto se guardan en caché: la primera descarga toma cerca de 2 horas y las siguientes, minutos. • Los precios con tarjeta CMR se excluyen de la comparación. | E9: 8 | F9: Must | G9: 4 | H9: 2 | I9: 1 | J9: Terminada | K9: Diego Fuentes | L9: 46286 | M9: d24a1c5
A10: HU06 | B10: E2 | C10: Como paciente, quiero que BioEqui incluya los precios de Profar, para sumar una cuarta cadena. | D10: • Dado el catálogo de Profar, cuando se descarga, entonces se obtienen los productos con su ficha de detalle. • La extracción cumple las reglas de la épica E8 (ver IMP-16). | E10: 5 | F10: Should | G10: 3 | H10: 3 | I10: 1 | J10: Terminada con observación | K10: Iván Fernández | L10: 46289 | M10: 0194174 · 9de3504
A11: HU07 | B11: E8 | C11: Como equipo, quiero revisar el robots.txt de cada fuente, aplicar pausas e identificarnos como proyecto académico, para extraer datos de forma ética y legal. | D11: • Cada fuente tiene su robots.txt revisado y la decisión queda registrada. • Ninguna fuente se consulta por rutas prohibidas ni sorteando medidas de seguridad. • No hay credenciales ni cookies en el código versionado. | E11: 3 | F11: Must | G11: 5 | H11: 1 | I11: 1 | J11: En curso | K11: Diego Fuentes e Iván Fernández | M11: Salcobrand y buscador del ISP descartados; Profar y Cruz Verde pendientes
A12: HU08 | B12: E3 | C12: Como equipo de datos, quiero vincular cada producto de farmacia con el catálogo del ISP por la raíz del registro sanitario, para saber qué productos están respaldados por el registro oficial. | D12: • Dado un producto con registro "F-8660", entonces se vincula con el medicamento de raíz "F-8660". • Cada producto queda con un estado: vinculado, sin_correspondencia, sin_registro, registro_invalido o registro_sospechoso. | E12: 5 | F12: Must | G12: 5 | H12: 2 | I12: 1 | J12: Terminada | K12: Diego Fuentes | L12: 46273 | M12: c2da72a
A13: HU09 | B13: E3 | C13: Como equipo de datos, quiero validar las vinculaciones y apartar las dudosas, para no agrupar medicamentos distintos. | D13: • El registro debe cumplir el formato ^[A-Z]{1,3}-\d+$. • El nombre publicado debe parecerse al nombre oficial (caso detectado: clopidogrel con el registro F-3901 de una clorfenamina). • Los productos que declaran menos principios activos de los que indica su nombre se marcan y no se agrupan (96 casos). | E13: 5 | F13: Must | G13: 5 | H13: 2 | I13: 1 | J13: Terminada | K13: Diego Fuentes | L13: 46275 | M13: c2da72a · 376552f
A14: HU10 | B14: E3 | C14: Como paciente, quiero que solo se comparen productos realmente intercambiables, para no comparar presentaciones distintas. | D14: • Dos productos son comparables solo si comparten principio activo, concentración, familia de forma farmacéutica y tamaño de envase. • Las formas de liberación modificada quedan en una familia aparte. | E14: 8 | F14: Must | G14: 5 | H14: 2 | I14: 1 | J14: Terminada | K14: Diego Fuentes | L14: 46273 | M14: c2da72a
A15: HU11 | B15: E3 | C15: Como paciente, quiero saber si la bioequivalencia la certifica el ISP o solo la declara la farmacia, para saber cuánto confiar en el dato. | D15: • La vista v_productos_vigentes entrega el origen del dato: isp, comercial o sin_dato. • La página muestra sello amarillo para lo certificado por el ISP y gris para lo declarado por la farmacia. | E15: 3 | F15: Must | G15: 5 | H15: 2 | I15: 1 | J15: Terminada | K15: Diego Fuentes | L15: 46285 | M15: 376552f · 605ecc4
A16: HU12 | B16: E4 | C16: Como equipo, quiero un esquema relacional en PostgreSQL ejecutándose en Docker, para persistir catálogo, oferta y precios. | D16: • El esquema v2 crea 6 tablas, índices y la vista v_productos_vigentes. • El contenedor bioequi_postgres_v2 queda disponible en el puerto 5433. | E16: 5 | F16: Must | G16: 5 | H16: 1 | I16: 1 | J16: Terminada | K16: Diego Fuentes e Iván Fernández | L16: 46275 | M16: cb801e9 · 376552f
A17: HU13 | B17: E4 | C17: Como analista, quiero que cada ejecución agregue el precio del día sin duplicarlo, para construir un historial confiable. | D17: • Existe la restricción UNIQUE (id_producto, fecha_muestreo). • Si el cargador se ejecuta dos veces el mismo día, actualiza en lugar de duplicar. • Los precios anteriores nunca se borran. | E17: 5 | F17: Must | G17: 4 | H17: 1 | I17: 1 | J17: Terminada | K17: Diego Fuentes e Iván Fernández | L17: 46275 | M17: 259618e · 376552f
A18: HU14 | B18: E5 | C18: Como paciente, quiero buscar por nombre o principio activo y ver las presentaciones disponibles, para encontrar el medicamento aunque no conozca la marca. | D18: • GET /buscar?q= exige 3 caracteres como mínimo. • Agrupa por principio activo, concentración y familia, sin considerar el envase. | E18: 5 | F18: Must | G18: 5 | H18: 3 | I18: 1 | J18: Terminada | K18: Diego Fuentes | L18: 46282 | M18: a53434c
A19: HU15 | B19: E5 | C19: Como paciente, quiero ver los tamaños de envase de una presentación, para elegir la cantidad que necesito. | D19: • GET /presentacion/{clave} devuelve los envases disponibles con su precio desde. | E19: 3 | F19: Must | G19: 4 | H19: 3 | I19: 1 | J19: Terminada | K19: Diego Fuentes | L19: 46282 | M19: a53434c
A20: HU16 | B20: E5 | C20: Como paciente, quiero comparar el precio de un mismo envase entre farmacias, para saber dónde me conviene comprar. | D20: • GET /comparar/{clave} ordena las farmacias por precio y calcula la diferencia en pesos y en porcentaje. • Incluye precio unitario, condición de venta y fecha de muestreo. | E20: 5 | F20: Must | G20: 5 | H20: 3 | I20: 1 | J20: Terminada | K20: Diego Fuentes | L20: 46282 | M20: a53434c
A21: HU17 | B21: E6 | C21: Como paciente, quiero una página donde buscar, elegir y comparar en tres pasos, para no tener que revisar cada farmacia por separado. | D21: • La página consume la API y muestra presentaciones, envases y comparación. • Cada producto tiene un botón "Ver en la farmacia" que enlaza al sitio real. | E21: 8 | F21: Must | G21: 5 | H21: 3 | I21: 1 | J21: Terminada | K21: Diego Fuentes | L21: 46285 | M21: 605ecc4
A22: HU18 | B22: E6 | C22: Como paciente, quiero ver el historial de precios de un producto, para saber si una oferta es real o permanente. | D22: • GET /producto/{id} entrega la serie, el mínimo, el máximo y los días en oferta (hecho). • La página muestra un gráfico de la serie (pendiente). | E22: 5 | F22: Should | G22: 4 | H22: 3 | I22: 3 | J22: En curso | K22: Iván Fernández | M22: API lista (a53434c); falta la vista en la página
A23: HU19 | B23: E6 | C23: Como paciente, quiero que los productos combinados muestren la dosis de cada principio activo, para no confundir "Ibuprofeno Paracetamol 300 mg". | D23: • Un producto con dos principios activos muestra ambas dosis en la tarjeta. | E23: 2 | F23: Should | G23: 3 | H23: 3 | I23: 3 | J23: Pendiente | K23: Diego Fuentes
A24: HU20 | B24: E6 | C24: Como paciente, quiero ver la fecha del precio y una advertencia de uso informativo, para no confundir un precio antiguo con uno vigente. | D24: • Cada precio muestra "Precio al AAAA-MM-DD". • La página advierte que no reemplaza la indicación de un profesional de la salud. | E24: 2 | F24: Must | G24: 4 | H24: 3 | I24: 1 | J24: Terminada | K24: Diego Fuentes | L24: 46285 | M24: 605ecc4
A25: HU21 | B25: E7 | C25: Como equipo de operación, quiero un script único que ejecute el flujo completo y se detenga ante errores, para actualizar los datos sin pasos manuales. | D25: • Ejecuta extracción, plata, oro y carga en orden. • Si un paso falla, se detiene y deja un registro en logs/. • Está versionado en el repositorio. | E25: 5 | F25: Should | G25: 4 | H25: 4 | I25: 3 | J25: En curso | K25: Iván Fernández | M25: actualizar.py existe en local para Dr. Simi; no está versionado
A26: HU22 | B26: E8 | C26: Como equipo, quiero que contraseñas y cookies no estén en el código versionado, para no exponer credenciales en un repositorio público. | D26: • docker-compose.yml y los extractores leen sus credenciales desde .env. • El .env está en .gitignore y existe un .env.example sin valores reales. | E26: 2 | F26: Must | G26: 5 | H26: 3 | I26: 3 | J26: Pendiente | K26: Diego Fuentes e Iván Fernández
A27: HU23 | B27: E3 | C27: Como equipo de datos, quiero recalcular las métricas de calidad con las cuatro farmacias, para reportar cifras actuales en el informe final. | D27: • Se informan grupos comparables, discrepancias, vinculaciones apartadas y cobertura por farmacia. | E27: 3 | F27: Must | G27: 5 | H27: 3 | I27: 3 | J27: Pendiente | K27: Diego Fuentes
A28: HU24 | B28: E7 | C28: Como equipo, quiero casos de prueba documentados para la API, la página y la carga, para demostrar que el sistema funciona. | D28: • Cada caso del plan de pruebas tiene resultado obtenido, fecha y evidencia. | E28: 5 | F28: Must | G28: 4 | H28: 4 | I28: 4 | J28: Pendiente | K28: Diego Fuentes e Iván Fernández
A29: HU25 | B29: E6 | C29: Como paciente, quiero una página clara y usable en celular, para consultar desde cualquier dispositivo. | D29: • La página se adapta a 375 px de ancho sin desplazamiento horizontal. | E29: 5 | F29: Could | G29: 3 | H29: 3 | I29: 3 | J29: Pendiente | K29: Iván Fernández
A30: HU26 | B30: E7 | C30: Como paciente, quiero acceder a BioEqui desde internet, para no depender del computador del equipo. | D30: • La base, la API y la página quedan publicadas en un servicio en la nube. | E30: 8 | F30: Could | G30: 2 | H30: 4 | I30: 4 | J30: No iniciada | K30: Diego Fuentes e Iván Fernández | M30: Opcional según disponibilidad de tiempo
A31: HU27 | B31: E4 | C31: Como analista, quiero muestrear los precios de las farmacias periódicamente, para acumular historial. | D31: • Se descargan las cadenas integradas en fechas sucesivas y quedan en bronce con su fecha. | E31: 3 | F31: Should | G31: 4 | H31: 2 | I31: 2 | J31: Terminada | K31: Iván Fernández | L31: 46307 | M31: 18479d9 · 105ce2b · cf60fc8
A32: HU28 | B32: E7 | C32: Como equipo, quiero el código centralizado en Desarrollo_Proyecto y un flujo develop → main, para entregar un repositorio ordenado. | D32: • Todo el código vive en Desarrollo_Proyecto. • main se actualiza desde develop mediante pull request. | E32: 3 | F32: Should | G32: 3 | H32: 2 | I32: 2 | J32: Terminada | K32: Iván Fernández | L32: 46304 | M32: 2504ca0 · 9de3504 · PR #8
A33: HU29 | B33: E7 | C33: Como equipo, quiero un entorno reproducible (requirements.txt y docker-compose v2), para que cualquiera levante el sistema. | D33: • Con requirements.txt y docker-compose.yml se levanta la base en el puerto 5433 y la API conecta sin errores. | E33: 3 | F33: Should | G33: 3 | H33: 2 | I33: 2 | J33: Terminada | K33: Diego Fuentes e Iván Fernández | L33: 46304 | M33: Informe 2.4 Desarrollo Proyecto (09-10-2026)
C35: Total story points | E35: =SUM(E5:E33) -> 138
C36: Story points terminados | E36: =SUMIF(J5:J33,"Terminada*",E5:E33) -> 100
C37: Avance | E37: =IF(E35=0,0,E36/E35) -> 0.72463768
